<?xml version="1.0" ?>
<robot name="./csv/sixdofarm" xmlns:xacro="http://www.ros.org/wiki/xacro">

  <property name="pi" value="3.14159265359"/>

  <material name="Red">
    <color rgba="1.0 0.0 0.0 1.0"/>
  </material>
  <material name="Green">
    <color rgba="0.0 1.0 0.0 1.0"/>
  </material>
  <material name="Blue">
    <color rgba="0.0 0.0 1.0 1.0"/>
  </material>
  


  <!-- world -->
  <link name="world"/>

  
  <joint name="world_2_base_link" type="fixed">
    <parent link="world"/>
    <child link="base_link"/>
    <origin rpy="0 0 0" xyz="0 0 0"/>
    
  </joint>
    
  


  <!-- base_link -->
  <link name="base_link">
    <collision>
      <origin rpy="0 0 0" xyz="0 0 0.0"/>
      <geometry>
        <box size="0.5 0.5 0"/>
      </geometry>
    </collision>
    <visual>
      <origin rpy="0 0 0" xyz="0 0 0.0"/>
      <geometry>
        <box size="0.5 0.5 0"/>
      </geometry>
      <material name="blue"/>
    </visual>
  
    <inertial>
      <origin rpy="0 0 0" xyz="0 0 0.0"/>
      <mass value = "0.001"/>
      <inertia ixx="0" ixy="0" ixz="0" iyy="0" iyz="0" izz="0"/>
    </inertial>
  
  </link>
 <gazebo reference="base_link">
    <material>Gazebo/blue</material>
  </gazebo>

  
  <joint name="base_link_2_Link1" type="fixed">
    <parent link="base_link"/>
    <child link="Link1"/>
    <origin rpy="0 0 0" xyz="0 0 0"/>
    
  </joint>
    
  


  <!-- Link1 -->
  <link name="Link1">
    <collision>
      <origin rpy="0 0 0" xyz="0 0 0.05"/>
      <geometry>
        <box size="0.05 0.05 0.1"/>
      </geometry>
    </collision>
    <visual>
      <origin rpy="0 0 0" xyz="0 0 0.05"/>
      <geometry>
        <box size="0.05 0.05 0.1"/>
      </geometry>
      <material name="red"/>
    </visual>
  
    <inertial>
      <origin rpy="0 0 0" xyz="0 0 0.05"/>
      <mass value="1"/>
      <inertia ixx="1" ixy="0" ixz="0" iyy="1" iyz="0" izz="1"/>
    </inertial>
    
  </link>
 <gazebo reference="Link1">
    <material>Gazebo/red</material>
  </gazebo>

  
  <joint name="Link1_2_Link2" type="revolute">
    <parent link="Link1"/>
    <child link="Link2"/>
    <origin rpy="0 0 0" xyz="0 0 0.1"/>
    
    <axis xyz="0 0 1"/>
    <limit effort="30" lower="-2.616" upper="2.617" velocity="1.571"/>
    
  </joint>
    
    <transmission name="trans_Link1_2_Link2">
      <type>transmission_interface/SimpleTransmission</type>
      <joint name="Link1_2_Link2"> 
        <hardwareInterface>EffortJointInterface</hardwareInterface>
      </joint>
      <actuator name="motor_Link1_2_Link2">
         <hardwareInterface>EffortJointInterface</hardwareInterface>
          <mechanicalReduction>1</mechanicalReduction>
      </actuator>
    </transmission>
    
  


  <!-- Link2 -->
  <link name="Link2">
    <collision>
      <origin rpy="0 0 0" xyz="0 0 0.05"/>
      <geometry>
        <box size="0 0 0"/>
      </geometry>
    </collision>
    <visual>
      <origin rpy="0 0 0" xyz="0 0 0.05"/>
      <geometry>
        <box size="0 0 0"/>
      </geometry>
      <material name="green"/>
    </visual>
  
    <inertial>
      <origin rpy="0 0 0" xyz="0 0 0.05"/>
      <mass value="1"/>
      <inertia ixx="1" ixy="0" ixz="0" iyy="1" iyz="0" izz="1"/>
    </inertial>
    
  </link>
 <gazebo reference="Link2">
    <material>Gazebo/green</material>
  </gazebo>

  
  <joint name="Link2_2_Link3" type="revolute">
    <parent link="Link2"/>
    <child link="Link3"/>
    <origin rpy="0 0 0" xyz="0 0 0"/>
    
    <axis xyz="0 1 0"/>
    <limit effort="30" lower="-2.616" upper="2.617" velocity="1.571"/>
    
  </joint>
    
    <transmission name="trans_Link2_2_Link3">
      <type>transmission_interface/SimpleTransmission</type>
      <joint name="Link2_2_Link3"> 
        <hardwareInterface>EffortJointInterface</hardwareInterface>
      </joint>
      <actuator name="motor_Link2_2_Link3">
         <hardwareInterface>EffortJointInterface</hardwareInterface>
          <mechanicalReduction>1</mechanicalReduction>
      </actuator>
    </transmission>
    
  


  <!-- Link3 -->
  <link name="Link3">
    <collision>
      <origin rpy="0 0 0" xyz="0 0 0.05"/>
      <geometry>
        <box size="0.05 0.05 0.1"/>
      </geometry>
    </collision>
    <visual>
      <origin rpy="0 0 0" xyz="0 0 0.05"/>
      <geometry>
        <box size="0.05 0.05 0.1"/>
      </geometry>
      <material name="blue"/>
    </visual>
  
    <inertial>
      <origin rpy="0 0 0" xyz="0 0 0.05"/>
      <mass value="1"/>
      <inertia ixx="1" ixy="0" ixz="0" iyy="1" iyz="0" izz="1"/>
    </inertial>
    
  </link>
 <gazebo reference="Link3">
    <material>Gazebo/blue</material>
  </gazebo>

  
  <joint name="Link3_2_Link4" type="revolute">
    <parent link="Link3"/>
    <child link="Link4"/>
    <origin rpy="0 0 0" xyz="0 0 0.1"/>
    
    <axis xyz="0 1 0"/>
    <limit effort="30" lower="-2.616" upper="2.617" velocity="1.571"/>
    
  </joint>
    
    <transmission name="trans_Link3_2_Link4">
      <type>transmission_interface/SimpleTransmission</type>
      <joint name="Link3_2_Link4"> 
        <hardwareInterface>EffortJointInterface</hardwareInterface>
      </joint>
      <actuator name="motor_Link3_2_Link4">
         <hardwareInterface>EffortJointInterface</hardwareInterface>
          <mechanicalReduction>1</mechanicalReduction>
      </actuator>
    </transmission>
    
  


  <!-- Link4 -->
  <link name="Link4">
    <collision>
      <origin rpy="0 0 0" xyz="0 0 0.05"/>
      <geometry>
        <box size="0.05 0.05 0.1"/>
      </geometry>
    </collision>
    <visual>
      <origin rpy="0 0 0" xyz="0 0 0.05"/>
      <geometry>
        <box size="0.05 0.05 0.1"/>
      </geometry>
      <material name="red"/>
    </visual>
  
    <inertial>
      <origin rpy="0 0 0" xyz="0 0 0.05"/>
      <mass value="1"/>
      <inertia ixx="1" ixy="0" ixz="0" iyy="1" iyz="0" izz="1"/>
    </inertial>
    
  </link>
 <gazebo reference="Link4">
    <material>Gazebo/red</material>
  </gazebo>

  
  <joint name="Link4_2_Link5" type="revolute">
    <parent link="Link4"/>
    <child link="Link5"/>
    <origin rpy="0 0 0" xyz="0 0 0.1"/>
    
    <axis xyz="0 0 1"/>
    <limit effort="30" lower="-2.616" upper="2.617" velocity="1.571"/>
    
  </joint>
    
    <transmission name="trans_Link4_2_Link5">
      <type>transmission_interface/SimpleTransmission</type>
      <joint name="Link4_2_Link5"> 
        <hardwareInterface>EffortJointInterface</hardwareInterface>
      </joint>
      <actuator name="motor_Link4_2_Link5">
         <hardwareInterface>EffortJointInterface</hardwareInterface>
          <mechanicalReduction>1</mechanicalReduction>
      </actuator>
    </transmission>
    
  


  <!-- Link5 -->
  <link name="Link5">
    <collision>
      <origin rpy="0 0 0" xyz="0 0 0.05"/>
      <geometry>
        <box size="0 0 0"/>
      </geometry>
    </collision>
    <visual>
      <origin rpy="0 0 0" xyz="0 0 0.05"/>
      <geometry>
        <box size="0 0 0"/>
      </geometry>
      <material name="green"/>
    </visual>
  
    <inertial>
      <origin rpy="0 0 0" xyz="0 0 0.05"/>
      <mass value="1"/>
      <inertia ixx="1" ixy="0" ixz="0" iyy="1" iyz="0" izz="1"/>
    </inertial>
    
  </link>
 <gazebo reference="Link5">
    <material>Gazebo/green</material>
  </gazebo>

  
  <joint name="Link5_2_Link6" type="revolute">
    <parent link="Link5"/>
    <child link="Link6"/>
    <origin rpy="0 0 0" xyz="0 0 0"/>
    
    <axis xyz="0 1 0"/>
    <limit effort="30" lower="-2.616" upper="2.617" velocity="1.571"/>
    
  </joint>
    
    <transmission name="trans_Link5_2_Link6">
      <type>transmission_interface/SimpleTransmission</type>
      <joint name="Link5_2_Link6"> 
        <hardwareInterface>EffortJointInterface</hardwareInterface>
      </joint>
      <actuator name="motor_Link5_2_Link6">
         <hardwareInterface>EffortJointInterface</hardwareInterface>
          <mechanicalReduction>1</mechanicalReduction>
      </actuator>
    </transmission>
    
  


  <!-- Link6 -->
  <link name="Link6">
    <collision>
      <origin rpy="0 0 0" xyz="0 0 0.05"/>
      <geometry>
        <box size="0.05 0.05 0.1"/>
      </geometry>
    </collision>
    <visual>
      <origin rpy="0 0 0" xyz="0 0 0.05"/>
      <geometry>
        <box size="0.05 0.05 0.1"/>
      </geometry>
      <material name="blue"/>
    </visual>
  
    <inertial>
      <origin rpy="0 0 0" xyz="0 0 0.05"/>
      <mass value="1"/>
      <inertia ixx="1" ixy="0" ixz="0" iyy="1" iyz="0" izz="1"/>
    </inertial>
    
  </link>
 <gazebo reference="Link6">
    <material>Gazebo/blue</material>
  </gazebo>

  
  <joint name="Link6_2_Link7" type="revolute">
    <parent link="Link6"/>
    <child link="Link7"/>
    <origin rpy="0 0 0" xyz="0 0 0.1"/>
    
    <axis xyz="0 0 1"/>
    <limit effort="30" lower="-2.616" upper="2.617" velocity="1.571"/>
    
  </joint>
    
    <transmission name="trans_Link6_2_Link7">
      <type>transmission_interface/SimpleTransmission</type>
      <joint name="Link6_2_Link7"> 
        <hardwareInterface>EffortJointInterface</hardwareInterface>
      </joint>
      <actuator name="motor_Link6_2_Link7">
         <hardwareInterface>EffortJointInterface</hardwareInterface>
          <mechanicalReduction>1</mechanicalReduction>
      </actuator>
    </transmission>
    
  


  <!-- Link7 -->
  <link name="Link7">
    <collision>
      <origin rpy="0 0 0" xyz="0 0 0.05"/>
      <geometry>
        <box size="0.05 0.05 0.1"/>
      </geometry>
    </collision>
    <visual>
      <origin rpy="0 0 0" xyz="0 0 0.05"/>
      <geometry>
        <box size="0.05 0.05 0.1"/>
      </geometry>
      <material name="red"/>
    </visual>
  
    <inertial>
      <origin rpy="0 0 0" xyz="0 0 0.05"/>
      <mass value="1"/>
      <inertia ixx="1" ixy="0" ixz="0" iyy="1" iyz="0" izz="1"/>
    </inertial>
    
  </link>
 <gazebo reference="Link7">
    <material>Gazebo/red</material>
  </gazebo>

  


  <gazebo>
    <plugin name="gazebo_ros_control" filename="libgazebo_ros_control.so">
      <robotNamespace>/./csv/sixdofarm</robotNamespace>
    </plugin>
  </gazebo>

</robot>
